Workbook

Sheet Lists
A1: Arizona Diamondbacks
A2: Atlanta Braves
A3: Baltimore Orioles
A4: Boston Red Sox
A5: Chicago Cubs
A6: Chicago White Sox
A7: Cincinnati Reds
A8: Cleveland Guardians
A9: Colorado Rockies
A10: Detroit Tigers
A11: Houston Astros
A12: Kansas City Royals
... A30: Washington Nationals

Sheet Game Input
A1: MLB BETTING MODEL — GAME INPUT
A3: MATCHUP | B3: HOME | C3: AWAY
A4: Team
A5: Starting Pitcher
A7: PITCHER STATS
A8: ERA
A9: FIP
A10: xFIP
A11: SIERA
A12: K/9
A13: BB/9
A14: BABIP
A15: HR/FB%
A16: GB%
... A30: CONTEXT
A31: Park Factor | B31: =IFERROR(VLOOKUP(B4,'Model Engine'!$A$2:$C$31,3,FALSE),100) | C31: =IFERROR(VLOOKUP(C4,'Model Engine'!$A$2:$C$31,3,FALSE),100)
A32: Wind Speed (mph)
A33: Wind Direction
A34: Temperature (°F)
A35: Days of Rest (Home)
A36: Days of Rest (Away)
A38: VEGAS LINES
A39: Moneyline Odds
A41: → Go to Results Dashboard sheet to see model output

Sheet Model Engine
A1: Team | B1: Park Name | C1: Park Factor
A2: Arizona Diamondbacks | B2: Chase Field | C2: 99
A3: Atlanta Braves | B3: Truist Park | C3: 102
A4: Baltimore Orioles | B4: Oriole Park | C4: 98
A5: Boston Red Sox | B5: Fenway Park | C5: 106
A6: Chicago Cubs | B6: Wrigley Field | C6: 103
A7: Chicago White Sox | B7: Guaranteed Rate Field | C7: 97
A8: Cincinnati Reds | B8: Great American Ball Park | C8: 105
A9: Cleveland Guardians | B9: Progressive Field | C9: 97
A10: Colorado Rockies | B10: Coors Field | C10: 115
A11: Detroit Tigers | B11: Comerica Park | C11: 99
A12: Houston Astros | B12: Minute Maid Park | C12: 101
A13: Kansas City Royals | B13: Kauffman Stadium | C13: 98
... A31: Washington Nationals | B31: Nationals Park | C31: 97
A34: MODEL CALCULATIONS
A35: Home Pitcher Score
B36: =MAX(0,MIN(100,(((4.20-'Game Input'!B9)/4.20)*30)+(((4.15-'Game Input'!B10)/4.15)*25)+(((4.10-'Game Input'!B11)/4.10)*20)+(((('Game Input'!B12)-8.9)/8.9)*10)+(((3.2-'Game Input'!B13)/3.2)*10)+(((4.20-'Game Input'!B17)/4.20)*5)+50))
A37: Away Pitcher Score
B38: =MAX(0,MIN(100,(((4.20-'Game Input'!C9)/4.20)*30)+(((4.15-'Game Input'!C10)/4.15)*25)+(((4.10-'Game Input'!C11)/4.10)*20)+(((('Game Input'!C12)-8.9)/8.9)*10)+(((3.2-'Game Input'!C13)/3.2)*10)+(((4.20-'Game Input'!C17)/4.20)*5)+50))
A39: Home Offense Score
B40: =MAX(0,MIN(100,((('Game Input'!B21-100)/100)*40)+(((('Game Input'!B20)-0.315)/0.315)*35)+(((('Game Input'!B24)-8.5)/8.5)*15)+(((('Game Input'!B23)-0.315)/0.315)*10)+50))
A41: Away Offense Score
B42: =MAX(0,MIN(100,((('Game Input'!C21-100)/100)*40)+(((('Game Input'!C20)-0.315)/0.315)*35)+(((('Game Input'!C24)-8.5)/8.5)*15)+(((('Game Input'!C23)-0.315)/0.315)*10)+50))
A43: Home Bullpen Score
B44: =MAX(0,MIN(100,((4.30-'Game Input'!B27)/4.30)*60+((2.0-'Game Input'!B28)/2.0)*40+50))
A45: Away Bullpen Score
B46: =MAX(0,MIN(100,((4.30-'Game Input'!C27)/4.30)*60+((2.0-'Game Input'!C28)/2.0)*40+50))
A47: Park Factor Adj (Home)
B48: =('Game Input'!B31-100)/100*0.3
A49: Wind Adj
B50: =IF('Game Input'!B33="Out",'Game Input'!B32*0.02,IF('Game Input'!B33="In",-'Game Input'!B32*0.015,0))
A51: Temp Adj
B52: =IF('Game Input'!B34<72,-(72-'Game Input'!B34)/10*0.005,0)
A53: Rest Adj (Home)
B54: =IF(('Game Input'!B35-'Game Input'!C36)>=2,0.03,IF(('Game Input'!C36-'Game Input'!B35)>=2,-0.03,0))
A55: Expected Runs — Home
B56: =MAX(1.5,MIN(12,3.5+(B40/100)*3+(-B38/100)*1.5+(B44/100)*1+B48+B50+B52+B54))
A57: Expected Runs — Away
B58: =MAX(1.5,MIN(12,3.5+(B42/100)*3+(-B36/100)*1.5+(B46/100)*1+B48+B50+B52-B54))
A59: Run Differential
...

Sheet Results Dashboard
A1: MLB BETTING MODEL — RESULTS DASHBOARD
A3: Matchup: | B3: ='Game Input'!B4 | C3: VS | D3: ='Game Input'!C4
A5: MATCHUP SUMMARY
A6: MODEL WIN PROBABILITY
A7: Home Win Prob | B7: =TEXT('Model Engine'!B62,"0.0%") | C7: Away Win Prob | D7: =TEXT('Model Engine'!B64,"0.0%")
A8: VEGAS IMPLIED PROBABILITY
A9: Home Implied | B9: =TEXT('Model Engine'!B66,"0.0%") | C9: Away Implied | D9: =TEXT('Model Engine'!B68,"0.0%")
A10: EDGE %
A11: Home Edge | B11: ='Model Engine'!B70 | C11: Away Edge | D11: ='Model Engine'!B72
A13: RECOMMENDATION
B14: =IF(AND('Model Engine'!B70>0.05,'Model Engine'!B70>'Model Engine'!B72),"BET HOME",IF(AND('Model Engine'!B72>0.05,'Model Engine'!B72>'Model Engine'!B70),"BET AWAY","NO VALUE"))
A15: Confidence Level: | B15: ='Model Engine'!B80
A16: Expected Total Runs: | B16: ='Model Engine'!B78
A18: PITCHER COMPARISON
A19: Stat | B19: Home Pitcher | C19: Away Pitcher
A20: ERA | B20: ='Game Input'!B8 | C20: ='Game Input'!C8
A21: FIP | B21: ='Game Input'!B9 | C21: ='Game Input'!C9
A22: xFIP | B22: ='Game Input'!B10 | C22: ='Game Input'!C10
A23: SIERA | B23: ='Game Input'!B11 | C23: ='Game Input'!C11
A24: K/9 | B24: ='Game Input'!B12 | C24: ='Game Input'!C12
A25: BB/9 | B25: ='Game Input'!B13 | C25: ='Game Input'!C13
A26: Recent Form ERA | B26: ='Game Input'!B17 | C26: ='Game Input'!C17
A28: CONTEXT SUMMARY
A29: Park Factor | B29: ='Game Input'!B31
A30: Wind | B30: =IF('Game Input'!B33="","—",'Game Input'!B33&" "&'Game Input'!B32&" mph")
A31: Temperature | B31: ='Game Input'!B34&" °F"
A32: Home Rest | B32: ='Game Input'!B35&" days"
A33: Away Rest | B33: ='Game Input'!C36&" days"

Sheet Bet Tracker
A1: BET TRACKER
A3: SUMMARY STATS
A4: Total Bets | B4: =COUNTA(A11:A1000)
A5: Win % | B5: =IFERROR(COUNTIF(G11:G1000,"W")/COUNTA(G11:G1000),0)
A6: Total P&L | B6: =SUM(H11:H1000)
A7: ROI % | B7: =IFERROR(SUM(H11:H1000)/SUM(F11:F1000),0)
A8: Current Bankroll | B8: =1000+SUM(H11:H1000)
A10: Date | B10: Home Team | C10: Away Team | D10: Bet Side | E10: Moneyline Odds | F10: Stake ($) | G10: Result | H10: Profit/Loss | I10: Running Bankroll | J10: ROI %
A11: 5/1/2026 | B11: New York Yankees | C11: Boston Red Sox | D11: HOME | E11: -150 | F11: 100 | G11: W | H11: =IF(G11="W",IF(E11<0,F11/ABS(E11)*100,F11*E11/100),IF(G11="L",-F11,"")) | I11: =1000+SUM(H$11:H11) | J11: =IFERROR(SUM(H$11:H11)/SUM(F$11:F11),"")
A12: 5/2/2026 | B12: Los Angeles Dodgers | C12: San Diego Padres | D12: AWAY | E12: 130 | F12: 50 | G12: L | H12: =IF(G12="W",IF(E12<0,F12/ABS(E12)*100,F12*E12/100),IF(G12="L",-F12,"")) | I12: =1000+SUM(H$11:H12) | J12: =IFERROR(SUM(H$11:H12)/SUM(F$11:F12),"")
A13: 5/3/2026 | B13: Atlanta Braves | C13: Philadelphia Phillies | D13: HOME | E13: -120 | F13: 75 | G13: W | H13: =IF(G13="W",IF(E13<0,F13/ABS(E13)*100,F13*E13/100),IF(G13="L",-F13,"")) | I13: =1000+SUM(H$11:H13) | J13: =IFERROR(SUM(H$11:H13)/SUM(F$11:F13),"")
H14: =IF(G14="W",IF(E14<0,F14/ABS(E14)*100,F14*E14/100),IF(G14="L",-F14,"")) | I14: =IF(COUNTA(A$11:A14)=0,"",1000+SUM(H$11:H14)) | J14: =IFERROR(SUM(H$11:H14)/SUM(F$11:F14),"")
H15: =IF(G15="W",IF(E15<0,F15/ABS(E15)*100,F15*E15/100),IF(G15="L",-F15,"")) | I15: =IF(COUNTA(A$11:A15)=0,"",1000+SUM(H$11:H15)) | J15: =IFERROR(SUM(H$11:H15)/SUM(F$11:F15),"")
H16: =IF(G16="W",IF(E16<0,F16/ABS(E16)*100,F16*E16/100),IF(G16="L",-F16,"")) | I16: =IF(COUNTA(A$11:A16)=0,"",1000+SUM(H$11:H16)) | J16: =IFERROR(SUM(H$11:H16)/SUM(F$11:F16),"")
H17: =IF(G17="W",IF(E17<0,F17/ABS(E17)*100,F17*E17/100),IF(G17="L",-F17,"")) | I17: =IF(COUNTA(A$11:A17)=0,"",1000+SUM(H$11:H17)) | J17: =IFERROR(SUM(H$11:H17)/SUM(F$11:F17),"")
H18: =IF(G18="W",IF(E18<0,F18/ABS(E18)*100,F18*E18/100),IF(G18="L",-F18,"")) | I18: =IF(COUNTA(A$11:A18)=0,"",1000+SUM(H$11:H18)) | J18: =IFERROR(SUM(H$11:H18)/SUM(F$11:F18),"")
H19: =IF(G19="W",IF(E19<0,F19/ABS(E19)*100,F19*E19/100),IF(G19="L",-F19,"")) | I19: =IF(COUNTA(A$11:A19)=0,"",1000+SUM(H$11:H19)) | J19: =IFERROR(SUM(H$11:H19)/SUM(F$11:F19),"")
H20: =IF(G20="W",IF(E20<0,F20/ABS(E20)*100,F20*E20/100),IF(G20="L",-F20,"")) | I20: =IF(COUNTA(A$11:A20)=0,"",1000+SUM(H$11:H20)) | J20: =IFERROR(SUM(H$11:H20)/SUM(F$11:F20),"")
H21: =IF(G21="W",IF(E21<0,F21/ABS(E21)*100,F21*E21/100),IF(G21="L",-F21,"")) | I21: =IF(COUNTA(A$11:A21)=0,"",1000+SUM(H$11:H21)) | J21: =IFERROR(SUM(H$11:H21)/SUM(F$11:F21),"")
H22: =IF(G22="W",IF(E22<0,F22/ABS(E22)*100,F22*E22/100),IF(G22="L",-F22,"")) | I22: =IF(COUNTA(A$11:A22)=0,"",1000+SUM(H$11:H22)) | J22: =IFERROR(SUM(H$11:H22)/SUM(F$11:F22),"")
H23: =IF(G23="W",IF(E23<0,F23/ABS(E23)*100,F23*E23/100),IF(G23="L",-F23,"")) | I23: =IF(COUNTA(A$11:A23)=0,"",1000+SUM(H$11:H23)) | J23: =IFERROR(SUM(H$11:H23)/SUM(F$11:F23),"")
H24: =IF(G24="W",IF(E24<0,F24/ABS(E24)*100,F24*E24/100),IF(G24="L",-F24,"")) | I24: =IF(COUNTA(A$11:A24)=0,"",1000+SUM(H$11:H24)) | J24: =IFERROR(SUM(H$11:H24)/SUM(F$11:F24),"")
H25: =IF(G25="W",IF(E25<0,F25/ABS(E25)*100,F25*E25/100),IF(G25="L",-F25,"")) | I25: =IF(COUNTA(A$11:A25)=0,"",1000+SUM(H$11:H25)) | J25: =IFERROR(SUM(H$11:H25)/SUM(F$11:F25),"")
... H200: =IF(G200="W",IF(E200<0,F200/ABS(E200)*100,F200*E200/100),IF(G200="L",-F200,"")) | I200: =IF(COUNTA(A$11:A200)=0,"",1000+SUM(H$11:H200)) | J200: =IFERROR(SUM(H$11:H200)/SUM(F$11:F200),"")

Sheet Reference & Glossary
A1: REFERENCE & GLOSSARY
A3: METRIC DEFINITIONS
A4: Metric | B4: Definition | C4: League Average | D4: Where to Find It
A5: FIP | B5: Fielding Independent Pitching. Measures pitcher performance based only on strikeouts, walks, and home runs — removes defense from the equation. Lower is better. | C5: 4.20 | D5: FanGraphs Leaderboards
A6: xFIP | B6: Expected FIP. Like FIP but normalizes HR/FB rate to league average. Better predictor of future performance than ERA. Lower is better. | C6: 4.15 | D6: FanGraphs Leaderboards
A7: SIERA | B7: Skill-Interactive ERA. Most advanced ERA estimator. Accounts for batted ball quality. Lower is better. | C7: 4.10 | D7: FanGraphs Leaderboards
A8: K/9 | B8: Strikeouts per 9 innings. Higher means more swing-and-miss ability. Reduces opponent's ability to put the ball in play. | C8: 8.9 | D8: FanGraphs / Baseball Reference
A9: BB/9 | B9: Walks per 9 innings. Lower is better. High BB/9 indicates control issues that inflate scoring. | C9: 3.2 | D9: FanGraphs / Baseball Reference
A10: wOBA | B10: Weighted On-Base Average. Weights each way of reaching base by its actual run value. Better than OBP or AVG alone. | C10: .315 | D10: FanGraphs Leaderboards
A11: wRC+ | B11: Weighted Runs Created Plus. Park- and league-adjusted offensive metric. 100 = league average. 120 = 20% above average. | C11: 100 | D11: FanGraphs Leaderboards
A12: BABIP | B12: Batting Average on Balls In Play. Measures luck/defense for pitchers, luck/skill for hitters. Extreme values tend to regress. | C12: .300 | D12: FanGraphs / Baseball Reference
A13: Barrel Rate | B13: % of batted balls hit with optimal exit velocity and launch angle. Strongly correlates with future offensive production. | C13: 8.5% | D13: Baseball Savant
A14: Park Factor | B14: Adjusts for how a ballpark affects run scoring. 100 = neutral. Above 100 = hitter-friendly, below 100 = pitcher-friendly. | C14: 100 | D14: Baseball Reference Park Factors
A15: Edge % | B15: Model Win Probability minus Vegas Implied Probability. Positive edge means the model thinks you have an advantage vs the line. | C15: N/A | D15: Calculated by this model
... A17: Implied Probability | B17: The win probability implied by the Vegas moneyline. -150 implies 60% chance of winning. | C17: N/A | D17: Calculated from moneyline
A19: HOW TO USE THE MODEL
A20: Step 1: Go to the 'Game Input' sheet.
A21: Step 2: Select Home and Away teams from the dropdown menus (Park Factor auto-populates).
A22: Step 3: Enter pitcher stats from FanGraphs.com → Pitchers → Leaderboards.
A23: Step 4: Enter team offensive stats from FanGraphs.com → Teams → Offensive stats.
A24: Step 5: Enter bullpen stats from FanGraphs.com → Teams → Relief pitchers (filter last 14 days).
A25: Step 6: Enter context factors (wind, temp from weather.com; rest days from team schedule).
A26: Step 7: Enter Vegas moneyline from your preferred sportsbook.
A27: Step 8: Navigate to 'Results Dashboard' to see the model output.
A28: Step 9: Only bet when Edge % > 5% and confidence is Medium or High.
A29: Step 10: Log every bet in the 'Bet Tracker' sheet to monitor ROI.
